func error_function() {
  raise "error";
  return 0;
}

func main() {
  var x;
  x = error_function() + 10;
  try {
    print(x); 
  }
  catch "error" {
    print("Caught an error during evaluation of x");
  }
}

/*
*OUT*
Caught an error during evaluation of x
*OUT*
*/